test_0 (__main__.lab1a.test_0)
[Lab 1] - [Investigation 3] - [Part 2] - printing - Test for file creation: ./lab1a.py ... ok
test_a (__main__.lab1a.test_a)
[Lab 1] - [Investigation 3] - [Part 2] - printing - Test for errors running: ./lab1a.py ... /usr/lib/python3.12/subprocess.py:822: ResourceWarning: unclosed file <_io.TextIOWrapper name=3 encoding='UTF-8'>
  _cleanup()
ResourceWarning: Enable tracemalloc to get the object allocation traceback
ok
test_a1 (__main__.lab1a.test_a1)
[Lab 1] - [Investigation 3] - [Part 2] - printing - Test for correct shebang line: ./lab1a.py ... ok
test_b (__main__.lab1a.test_b)
[Lab 1] - [Investigation 3] - [Part 2] - printing - Test output for correct output "Hello world": ./lab1a.py ... ok
test_0 (__main__.lab1b.test_0)
[Lab 1] - [Investigation 4] - string objects & printing - Test for file creation: ./lab1b.py ... ok
test_a (__main__.lab1b.test_a)
[Lab 1] - [Investigation 4] - string objects & printing - Test for errors running: ./lab1b.py ... ok
test_a1 (__main__.lab1b.test_a1)
[Lab 1] - [Investigation 4] - string objects & printing - Test for correct shebang line: ./lab1b.py ... ok
test_b (__main__.lab1b.test_b)
[Lab 1] - [Investigation 4] - string objects & printing - Test for correct output "How old are you Isaac?": ./lab1b.py ... ok
test_0 (__main__.lab1c.test_0)
[Lab 1] - [Investigation 4] - integer objects & printing - Test for file creation: ./lab1c.py ... FAIL

======================================================================
FAIL: test_0 (__main__.lab1c.test_0)
[Lab 1] - [Investigation 4] - integer objects & printing - Test for file creation: ./lab1c.py
----------------------------------------------------------------------
Traceback (most recent call last):
  File "/home/pgomez-moreno/OPS445/lab1/./CheckLab1.py", line 135, in test_0
    self.assertTrue( os.path.exists('./lab1c.py'), msg=error_output)
AssertionError: False is not true : your file cannot be found(HINT: make sure you AND your file are in the correct directory)

----------------------------------------------------------------------
Ran 9 tests in 0.062s

FAILED (failures=1)
OPS445 Lab Report - System Information for running ./CheckLab1.py
=================================================================
    User login name: pgomez-moreno
    Git Email: pgomez-moreno@myseneca.ca
    Linux system name: pgomezmoreno-VirtualBox
    Python executable: /usr/bin/python3
    Python version:  3.12.3 (main, Jan 17 2025, 18:03:48) [GCC 13.3.0]
    OS Platform: linux
    Working Directory: /home/pgomez-moreno/OPS445/lab1
    Start at: Tue Jan 21 12:27:22 2025
=================================================================
